Workbook

Sheet MODELO_AD_BI
B1: Portal de Atendimento do INSS - PAT
B2: Autodeclaração para o Requerimento de Benefício por Incapacidade
B3: Homologador:
B7: # | C7: LIBERADO | D7: MACROPROCESSO | E7: CASO DE TESTE | F7: CANAL | G7: PAPEL | H7: FLUXO | I7: PARÂMETROS | J7: RESULTADO ESPERADO | K7: DATA EXECUÇÃO | L7: MASSA | M7: STATUS CT | N7: RESULTADO ENCONTRADO | O7: ANÁLISE DATAPREV | P7: MELHORIAS
B8: =IF(ISERR(casostestes[[#This Row],[ID]]),"-",casostestes[[#This Row],[ID]]) -> 1 | C8: =IFERROR(IF(VLOOKUP($B8,casostestes[#Data],10)=0,"Não",VLOOKUP($B8,casostestes[#Data],10)), "-") -> Sim | D8: =IFERROR(IF(VLOOKUP($B8,casostestes[#Data],2)=0,"-",VLOOKUP($B8,casostestes[#Data],2)), "-") -> Requerimento Inicial de BI | E8: =IFERROR(IF(VLOOKUP($B8,casostestes[#Data],3)=0,"-",VLOOKUP($B8,casostestes[#Data],3)), "-") -> 6 Criação de tarefa de BI inicial com fluxo ATESTMED para categoria DIFERENTE de Segurado Especial COM exigência de preenchimento da AD. Premissas: Catálogo: Exige autodeclaração = ATIVADO Parâmetro: 144 - Fluxo ATESTMED = LIGADO | F8: =IFERROR(IF(VLOOKUP($B8,casostestes[#Data],4)=0,"-",VLOOKUP($B8,casostestes[#Data],4)),"-") -> Central 135 | G8: =IFERROR(IF(VLOOKUP($B8,casostestes[#Data],5)=0,"-",VLOOKUP($B8,casostestes[#Data],5)),"-") -> ATENDENTE_CENTRAL_135 | H8: =IFERROR(IF(VLOOKUP($B8,casostestes[#Data],6)=0,"-",VLOOKUP($B8,casostestes[#Data],6)),"-") -> 1. Logar no Portal do Atendimento INSS com o perfil do caso de teste 2. Criar tarefa de BI informando: - Tipo de Incapacidade? "Temporário" - A pessoa está presa? "Não" - Categoria do trabalhador "Desempregado" ... - A pessoa ficou sem trabalhar? "Sim" | I8: =IFERROR(IF(VLOOKUP($B8,casostestes[#Data],8)=0,"-",VLOOKUP($B8,casostestes[#Data],8)),"-") -> - | J8: =IFERROR(IF(VLOOKUP($B8,casostestes[#Data],9)=0,"-",VLOOKUP($B8,casostestes[#Data],9)),"-") -> 1. Na conclusão do requerimento é emitido o aviso: "É necessário apresentar os documentos no prazo de 5 dias. Caso não apresente, o pedido será cancelado." 2. A tarefa de BI criada com STATUS: EM EXIGÊNCIA 3. Status SIBE: Fluxo não iniciado 4. Tarefa COM as divergências: - 174 Ausência do atestado médico
B9: =IF(ISERR(casostestes[[#This Row],[ID]]),"-",casostestes[[#This Row],[ID]]) -> 2 | C9: =IFERROR(IF(VLOOKUP($B9,casostestes[#Data],10)=0,"Não",VLOOKUP($B9,casostestes[#Data],10)), "-") -> Sim | D9: =IFERROR(IF(VLOOKUP($B9,casostestes[#Data],2)=0,"-",VLOOKUP($B9,casostestes[#Data],2)), "-") -> Integração | E9: =IFERROR(IF(VLOOKUP($B9,casostestes[#Data],3)=0,"-",VLOOKUP($B9,casostestes[#Data],3)), "-") -> 12 Criar tarefa de BI inicial fluxo ATESTMEDQ para categoria "Segurado especial" onde o parâmetro "Exige Autodeclaração" no Catálogo está ATIVADO e foi respondida a autodeclaração COM período pendente **Parâmetro PAT ligado: 144 - Fluxo ATESTMEDQ | F9: =IFERROR(IF(VLOOKUP($B9,casostestes[#Data],4)=0,"-",VLOOKUP($B9,casostestes[#Data],4)),"-") -> PAT | G9: =IFERROR(IF(VLOOKUP($B9,casostestes[#Data],5)=0,"-",VLOOKUP($B9,casostestes[#Data],5)),"-") -> SERVIDOR | H9: =IFERROR(IF(VLOOKUP($B9,casostestes[#Data],6)=0,"-",VLOOKUP($B9,casostestes[#Data],6)),"-") -> 1. Logar no Portal do Atendimento INSS com o perfil do caso de teste 2.Criar tarefa de BI informando: Tipo de Incapacidade? "Temporária " A pessoa está presa? Não Categoria do trabalhador "Segurado Especial" A pessoa ficou sem trabalhar? Sim 3. Responder formulário da autodeclaração | I9: =IFERROR(IF(VLOOKUP($B9,casostestes[#Data],8)=0,"-",VLOOKUP($B9,casostestes[#Data],8)),"-") -> - | J9: =IFERROR(IF(VLOOKUP($B9,casostestes[#Data],9)=0,"-",VLOOKUP($B9,casostestes[#Data],9)),"-") -> Tarefa de BI criada com situação Pendente. Tarefa SEM Divergência de autodeclaração (116) Status SIBE igual a FLUXO NÃO INICIADO Aguardar até a geração automática do PDF da autodeclaração: DTP: Campo Exige_autodeclaração = 1 Campo DT_RETORNO_SES_CNIS deverá estar preenchido (Descritivo preenchido pelo CNIS) Tabela SES_CNIS_ANALISES (Indica a existência ou não de períodos pendentes) Status SIBE igual a AGUARDANDO ATESTADO Na opção "Lista de Ocorrências", o json de integração com o SIBE deverá conter o campo "periodosPendentesSegEsp" com valor true.
B10: =IF(ISERR(casostestes[[#This Row],[ID]]),"-",casostestes[[#This Row],[ID]]) -> 3 | C10: =IFERROR(IF(VLOOKUP($B10,casostestes[#Data],10)=0,"Não",VLOOKUP($B10,casostestes[#Data],10)), "-") -> Sim | D10: =IFERROR(IF(VLOOKUP($B10,casostestes[#Data],2)=0,"-",VLOOKUP($B10,casostestes[#Data],2)), "-") -> Integração | E10: =IFERROR(IF(VLOOKUP($B10,casostestes[#Data],3)=0,"-",VLOOKUP($B10,casostestes[#Data],3)), "-") -> 13 Criar tarefa de BI inicial fluxo ATESTMEDQ para categoria "Segurado especial" onde o parâmetro "Exige Autodeclaração" no Catálogo está ATIVADO e foi respondida a autodeclaração SEM período pendente **Parâmetro PAT ligado: 144 - Fluxo ATESTMEDQ | F10: =IFERROR(IF(VLOOKUP($B10,casostestes[#Data],4)=0,"-",VLOOKUP($B10,casostestes[#Data],4)),"-") -> PAT | G10: =IFERROR(IF(VLOOKUP($B10,casostestes[#Data],5)=0,"-",VLOOKUP($B10,casostestes[#Data],5)),"-") -> SERVIDOR | H10: =IFERROR(IF(VLOOKUP($B10,casostestes[#Data],6)=0,"-",VLOOKUP($B10,casostestes[#Data],6)),"-") -> 1. Logar no Portal do Atendimento INSS com o perfil do caso de teste 2.Criar tarefa de BI informando: Tipo de Incapacidade? "Temporária " A pessoa está presa? Não Categoria do trabalhador "Segurado Especial" A pessoa ficou sem trabalhar? Sim 3. Responder a autodeclaração | I10: =IFERROR(IF(VLOOKUP($B10,casostestes[#Data],8)=0,"-",VLOOKUP($B10,casostestes[#Data],8)),"-") -> - | J10: =IFERROR(IF(VLOOKUP($B10,casostestes[#Data],9)=0,"-",VLOOKUP($B10,casostestes[#Data],9)),"-") -> Tarefa de BI criada com situação Pendente. Tarefa SEM Divergência de autodeclaração (116) Status SIBE igual a FLUXO NÃO INICIADO Aguardar até a geração automática do PDF da autodeclaração: DTP: Campo Exige_autodeclaração = 1 Campo DT_RETORNO_SES_CNIS deverá estar preenchido (Descritivo preenchido pelo CNIS) Tabela SES_CNIS_ANALISES (Indica a existência ou não de períodos pendentes) Status SIBE igual a AGUARDANDO ATESTADO Na opção "Lista de Ocorrências", o json de integração com o SIBE deverá conter o campo "periodosPendentesSegEsp" com valor false.
B11: =IF(ISERR(casostestes[[#This Row],[ID]]),"-",casostestes[[#This Row],[ID]]) -> 4 | C11: =IFERROR(IF(VLOOKUP($B11,casostestes[#Data],10)=0,"Não",VLOOKUP($B11,casostestes[#Data],10)), "-") -> Sim | D11: =IFERROR(IF(VLOOKUP($B11,casostestes[#Data],2)=0,"-",VLOOKUP($B11,casostestes[#Data],2)), "-") -> Integração | E11: =IFERROR(IF(VLOOKUP($B11,casostestes[#Data],3)=0,"-",VLOOKUP($B11,casostestes[#Data],3)), "-") -> 16 Cumprir a exigência de autodeclaração | F11: =IFERROR(IF(VLOOKUP($B11,casostestes[#Data],4)=0,"-",VLOOKUP($B11,casostestes[#Data],4)),"-") -> PAT | G11: =IFERROR(IF(VLOOKUP($B11,casostestes[#Data],5)=0,"-",VLOOKUP($B11,casostestes[#Data],5)),"-") -> SERVIDOR | H11: =IFERROR(IF(VLOOKUP($B11,casostestes[#Data],6)=0,"-",VLOOKUP($B11,casostestes[#Data],6)),"-") -> 1. Logar no Portal do Atendimento INSS com o perfil Servidor 2.Consultar uma tarefa em exigência de autodeclaração e acionar Cumprir Exigência 3. Responder o formulário de autodeclaração até o final | I11: =IFERROR(IF(VLOOKUP($B11,casostestes[#Data],8)=0,"-",VLOOKUP($B11,casostestes[#Data],8)),"-") -> - | J11: =IFERROR(IF(VLOOKUP($B11,casostestes[#Data],9)=0,"-",VLOOKUP($B11,casostestes[#Data],9)),"-") -> Tarefa de BI com situação alterada para Pendente Divergência de autodeclaração (116) EXCLUÍDA da tarefa Aguardar até a geração automática do PDF da autodeclaração: DTP: Campo DT_RETORNO_SES_CNIS deverá estar preenchido (Descritivo preenchido pelo CNIS) Tabela SES_CNIS_ANALISES (Indica a existência ou não de períodos pendentes) Status SIBE igual a AGUARDANDO ATESTADO ou AGUARDANDO PERÍCIA (conforme a tarefa seja do fluxo ATESTMEDQ ou PRESENCIAL) Na opção "Lista de Ocorrências", o json de integração com o SIBE deverá conter o campo "periodosPendentesSegEsp" com valor true ou false, conforme tenha ou não períodos pendentes.
B12: =IF(ISERR(casostestes[[#This Row],[ID]]),"-",casostestes[[#This Row],[ID]]) -> 5 | C12: =IFERROR(IF(VLOOKUP($B12,casostestes[#Data],10)=0,"Não",VLOOKUP($B12,casostestes[#Data],10)), "-") -> Sim | D12: =IFERROR(IF(VLOOKUP($B12,casostestes[#Data],2)=0,"-",VLOOKUP($B12,casostestes[#Data],2)), "-") -> Integração | E12: =IFERROR(IF(VLOOKUP($B12,casostestes[#Data],3)=0,"-",VLOOKUP($B12,casostestes[#Data],3)), "-") -> 17 Responder o formulário de autodeclaração acessando diretamente a aba segurado especial ao detalhar a tarefa, onde a tarefa encontra-se em exigência de autodeclaração | F12: =IFERROR(IF(VLOOKUP($B12,casostestes[#Data],4)=0,"-",VLOOKUP($B12,casostestes[#Data],4)),"-") -> PAT | G12: =IFERROR(IF(VLOOKUP($B12,casostestes[#Data],5)=0,"-",VLOOKUP($B12,casostestes[#Data],5)),"-") -> SERVIDOR | H12: =IFERROR(IF(VLOOKUP($B12,casostestes[#Data],6)=0,"-",VLOOKUP($B12,casostestes[#Data],6)),"-") -> 1. Logar no Portal do Atendimento INSS com o perfil Servidor 2.Consultar uma tarefa em exigência de autodeclaração 3. Acionar a aba Segurado especial 3. Responder o formulário de autodeclaração até o final | I12: =IFERROR(IF(VLOOKUP($B12,casostestes[#Data],8)=0,"-",VLOOKUP($B12,casostestes[#Data],8)),"-") -> - | J12: =IFERROR(IF(VLOOKUP($B12,casostestes[#Data],9)=0,"-",VLOOKUP($B12,casostestes[#Data],9)),"-") -> Tarefa de BI com situação alterada para Pendente Divergência de autodeclaração (116) EXCLUÍDA da tarefa Aguardar até a geração automática do PDF da autodeclaração: Status SIBE igual a AGUARDANDO ATESTADO ou AGUARDANDO PERÍCIA (conforme a tarefa seja do fluxo ATESTMEDQ ou PRESENCIAL) Na opção "Lista de Ocorrências", o json de integração com o SIBE deverá conter o campo "periodosPendentesSegEsp" com valor true ou false, conforme tenha ou não períodos pendentes.
B13: =IF(ISERR(casostestes[[#This Row],[ID]]),"-",casostestes[[#This Row],[ID]]) -> 6 | C13: =IFERROR(IF(VLOOKUP($B13,casostestes[#Data],10)=0,"Não",VLOOKUP($B13,casostestes[#Data],10)), "-") -> Sim | D13: =IFERROR(IF(VLOOKUP($B13,casostestes[#Data],2)=0,"-",VLOOKUP($B13,casostestes[#Data],2)), "-") -> Integração | E13: =IFERROR(IF(VLOOKUP($B13,casostestes[#Data],3)=0,"-",VLOOKUP($B13,casostestes[#Data],3)), "-") -> 18 Responder o formulário de autodeclaração acessando diretamente a aba segurado especial ao detalhar a tarefa, onde a tarefa encontra-se em exigência de documento médico | F13: =IFERROR(IF(VLOOKUP($B13,casostestes[#Data],4)=0,"-",VLOOKUP($B13,casostestes[#Data],4)),"-") -> PAT | G13: =IFERROR(IF(VLOOKUP($B13,casostestes[#Data],5)=0,"-",VLOOKUP($B13,casostestes[#Data],5)),"-") -> SERVIDOR | H13: =IFERROR(IF(VLOOKUP($B13,casostestes[#Data],6)=0,"-",VLOOKUP($B13,casostestes[#Data],6)),"-") -> 1. Logar no Portal do Atendimento INSS com o perfil Servidor 2.Consultar uma tarefa em exigência de documento médico 3. Acionar a aba Segurado especial 3. Responder o formulário de autodeclaração até o final | I13: =IFERROR(IF(VLOOKUP($B13,casostestes[#Data],8)=0,"-",VLOOKUP($B13,casostestes[#Data],8)),"-") -> - | J13: =IFERROR(IF(VLOOKUP($B13,casostestes[#Data],9)=0,"-",VLOOKUP($B13,casostestes[#Data],9)),"-") -> Tarefa de BI permanece em tarefa em exigência de documento médico Divergência de autodeclaração (116) EXCLUÍDA da tarefa Aguardar até a geração automática do PDF da autodeclaração: Status SIBE continua igual a FLUXO NÃO INICIADO, pois a tarefa encontra-se em exigência de documento médico
B14: =IF(ISERR(casostestes[[#This Row],[ID]]),"-",casostestes[[#This Row],[ID]]) -> 7 | C14: =IFERROR(IF(VLOOKUP($B14,casostestes[#Data],10)=0,"Não",VLOOKUP($B14,casostestes[#Data],10)), "-") -> Sim | D14: =IFERROR(IF(VLOOKUP($B14,casostestes[#Data],2)=0,"-",VLOOKUP($B14,casostestes[#Data],2)), "-") -> Integração | E14: =IFERROR(IF(VLOOKUP($B14,casostestes[#Data],3)=0,"-",VLOOKUP($B14,casostestes[#Data],3)), "-") -> 19 Criar tarefa de BI inicial fluxo ATESTMEDQ para categoria "Segurado especial" onde o parâmetro "Exige Autodeclaração" no Catálogo está ATIVADO, NÃO foi respondida a autodeclaração, NÃO foi incluído o anexo detalhado de AD e cidadão está preso **Parâmetro PAT ligado: 144 - Fluxo ATESTMEDQ | F14: =IFERROR(IF(VLOOKUP($B14,casostestes[#Data],4)=0,"-",VLOOKUP($B14,casostestes[#Data],4)),"-") -> PAT | G14: =IFERROR(IF(VLOOKUP($B14,casostestes[#Data],5)=0,"-",VLOOKUP($B14,casostestes[#Data],5)),"-") -> SERVIDOR | H14: =IFERROR(IF(VLOOKUP($B14,casostestes[#Data],6)=0,"-",VLOOKUP($B14,casostestes[#Data],6)),"-") -> 1. Logar no Portal do Atendimento INSS com o perfil do caso de teste 2.Criar tarefa de BI informando: Tipo de Incapacidade? "Temporária " A pessoa está presa? Sim Categoria do trabalhador "Segurado Especial" A pessoa ficou sem trabalhar? Sim 3. NÃO Informar anexo detalhado de autodeclaração 4. NÃO responder o formulário de autodeclaração | I14: =IFERROR(IF(VLOOKUP($B14,casostestes[#Data],8)=0,"-",VLOOKUP($B14,casostestes[#Data],8)),"-") -> - | J14: =IFERROR(IF(VLOOKUP($B14,casostestes[#Data],9)=0,"-",VLOOKUP($B14,casostestes[#Data],9)),"-") -> Tarefa de BI criada com situação Pendente. Divergência de autodeclaração (116) incluída na tarefa Após execução workflow: Tarefa de BI com situação alterada para Exigência . Após alguns minutos: Tarefa de BI com situação Concluída. Status SIBE igual a INDEFERIDO Na opção "Lista de Ocorrências", o json de integração com o SIBE deverá conter o campo "periodosPendentesSegEsp" com valor NULL DTP: Campo Exige_autodeclaração = 0
B15: =IF(ISERR(casostestes[[#This Row],[ID]]),"-",casostestes[[#This Row],[ID]]) -> 8 | C15: =IFERROR(IF(VLOOKUP($B15,casostestes[#Data],10)=0,"Não",VLOOKUP($B15,casostestes[#Data],10)), "-") -> Sim | D15: =IFERROR(IF(VLOOKUP($B15,casostestes[#Data],2)=0,"-",VLOOKUP($B15,casostestes[#Data],2)), "-") -> Integração | E15: =IFERROR(IF(VLOOKUP($B15,casostestes[#Data],3)=0,"-",VLOOKUP($B15,casostestes[#Data],3)), "-") -> 20 Criar tarefa de BI inicial fluxo ATESTMEDQ para categoria "Segurado especial" onde o parâmetro "Exige Autodeclaração" no Catálogo está ATIVADO, NÃO foi respondida a autodeclaração, NÃO foi incluído o anexo detalhado de AD e cidadão ficou sem trabalhar **Parâmetro PAT ligado: 144 - Fluxo ATESTMEDQ | F15: =IFERROR(IF(VLOOKUP($B15,casostestes[#Data],4)=0,"-",VLOOKUP($B15,casostestes[#Data],4)),"-") -> PAT | G15: =IFERROR(IF(VLOOKUP($B15,casostestes[#Data],5)=0,"-",VLOOKUP($B15,casostestes[#Data],5)),"-") -> SERVIDOR | H15: =IFERROR(IF(VLOOKUP($B15,casostestes[#Data],6)=0,"-",VLOOKUP($B15,casostestes[#Data],6)),"-") -> 1. Logar no Portal do Atendimento INSS com o perfil do caso de teste 2.Criar tarefa de BI informando: Tipo de Incapacidade? "Temporária " A pessoa está presa? Não Categoria do trabalhador "Segurado Especial" A pessoa ficou sem trabalhar? Não 3. Informar anexo detalhado de autodeclaração 4. NÃO responder o formulário de autodeclaração | I15: =IFERROR(IF(VLOOKUP($B15,casostestes[#Data],8)=0,"-",VLOOKUP($B15,casostestes[#Data],8)),"-") -> - | J15: =IFERROR(IF(VLOOKUP($B15,casostestes[#Data],9)=0,"-",VLOOKUP($B15,casostestes[#Data],9)),"-") -> Tarefa de BI criada com situação Pendente. Divergência de autodeclaração (116) incluída na tarefa Após execução workflow: Tarefa de BI com situação alterada para Exigência . Após alguns minutos: Tarefa de BI com situação Concluída. Status SIBE igual a INDEFERIDO Na opção "Lista de Ocorrências", o json de integração com o SIBE deverá conter o campo "periodosPendentesSegEsp" com valor NULL DTP: Campo Exige_autodeclaração = 0
B16: =IF(ISERR(casostestes[[#This Row],[ID]]),"-",casostestes[[#This Row],[ID]]) -> 9 | C16: =IFERROR(IF(VLOOKUP($B16,casostestes[#Data],10)=0,"Não",VLOOKUP($B16,casostestes[#Data],10)), "-") -> Sim | D16: =IFERROR(IF(VLOOKUP($B16,casostestes[#Data],2)=0,"-",VLOOKUP($B16,casostestes[#Data],2)), "-") -> Integração | E16: =IFERROR(IF(VLOOKUP($B16,casostestes[#Data],3)=0,"-",VLOOKUP($B16,casostestes[#Data],3)), "-") -> 21 Criar tarefa de BI inicial fluxo ATESTMEDQ para categoria "Segurado especial" onde o parâmetro "Exige Autodeclaração" no Catálogo está ATIVADO, NÃO foi respondida a autodeclaração e foi incluído o anexo detalhado de AD **Parâmetro PAT ligado: 144 - Fluxo ATESTMEDQ | F16: =IFERROR(IF(VLOOKUP($B16,casostestes[#Data],4)=0,"-",VLOOKUP($B16,casostestes[#Data],4)),"-") -> PAT | G16: =IFERROR(IF(VLOOKUP($B16,casostestes[#Data],5)=0,"-",VLOOKUP($B16,casostestes[#Data],5)),"-") -> SERVIDOR | H16: =IFERROR(IF(VLOOKUP($B16,casostestes[#Data],6)=0,"-",VLOOKUP($B16,casostestes[#Data],6)),"-") -> 1. Logar no Portal do Atendimento INSS com o perfil do caso de teste 2.Criar tarefa de BI informando: Tipo de Incapacidade? "Temporária " A pessoa está presa? Não Categoria do trabalhador "Segurado Especial" A pessoa ficou sem trabalhar? Sim 3. Informar anexo detalhado de autodeclaração 4. NÃO responder o formulário de autodeclaração Resultado 1 5.Alterar via banco de dados a data da exigência para (data atual - 36 dias) Resultado 2 | I16: =IFERROR(IF(VLOOKUP($B16,casostestes[#Data],8)=0,"-",VLOOKUP($B16,casostestes[#Data],8)),"-") -> - | J16: =IFERROR(IF(VLOOKUP($B16,casostestes[#Data],9)=0,"-",VLOOKUP($B16,casostestes[#Data],9)),"-") -> Resultado 1:' Tarefa de BI criada com situação Pendente. Divergência de autodeclaração (116) incluída na tarefa Após execução workflow: Tarefa de BI com situação alterada para Exigência . Status SIBE igual a FLUXO NÃO INICIADO DTP: Campo Exige_autodeclaração = 2 Resultado 2 - Após alguns minutos: Tarefa de BI com situação alterada para Pendente Despacho incluído informando a operação ( fragmento de sigla XXXXXXXXXX ) Divergência de autodeclaração (116) EXCLUÍDA da tarefa Alguns minutos depois: Status SIBE igual a AGUARDANDO ATESTADO Na opção "Lista de Ocorrências", o json de integração com o SIBE deverá conter o campo "periodosPendentesSegEsp" com valor true.
B17: =IF(ISERR(casostestes[[#This Row],[ID]]),"-",casostestes[[#This Row],[ID]]) -> 10 | C17: =IFERROR(IF(VLOOKUP($B17,casostestes[#Data],10)=0,"Não",VLOOKUP($B17,casostestes[#Data],10)), "-") -> Sim | D17: =IFERROR(IF(VLOOKUP($B17,casostestes[#Data],2)=0,"-",VLOOKUP($B17,casostestes[#Data],2)), "-") -> Integração | E17: =IFERROR(IF(VLOOKUP($B17,casostestes[#Data],3)=0,"-",VLOOKUP($B17,casostestes[#Data],3)), "-") -> 22 Criar tarefa de BI inicial fluxo PRESENCIAL para categoria "Segurado especial" onde o parâmetro "Exige Autodeclaração" no Catálogo está ATIVADO, NÃO foi respondida a autodeclaração e NÃO foi incluído o anexo detalhado de AD **Parâmetro PAT ligado: 144 - Fluxo ATESTMEDQ **Parâmetro PAT ligado: 109 -Tipo de Incapacidade Permanente leva à Fluxo Presencial do Novo BI | F17: =IFERROR(IF(VLOOKUP($B17,casostestes[#Data],4)=0,"-",VLOOKUP($B17,casostestes[#Data],4)),"-") -> PAT | G17: =IFERROR(IF(VLOOKUP($B17,casostestes[#Data],5)=0,"-",VLOOKUP($B17,casostestes[#Data],5)),"-") -> SERVIDOR | H17: =IFERROR(IF(VLOOKUP($B17,casostestes[#Data],6)=0,"-",VLOOKUP($B17,casostestes[#Data],6)),"-") -> 1. Logar no Portal do Atendimento INSS com o perfil do caso de teste 2.Criar tarefa de BI informando: Tipo de Incapacidade? "Permanente" A pessoa está presa? Não Houve acidente de trabalho? Não Categoria do trabalhador "Segurado Especial" A pessoa ficou sem trabalhar? Sim 3. NÃO informar anexo detalhado de autodeclaração 5. Realizar agendamento 6. NÃO responder o formulário de autodeclaração Resultado 1 7.Alterar via banco de dados a data da exigência para (data atual - 36 dias) Resulado 2 | I17: =IFERROR(IF(VLOOKUP($B17,casostestes[#Data],8)=0,"-",VLOOKUP($B17,casostestes[#Data],8)),"-") -> - | J17: =IFERROR(IF(VLOOKUP($B17,casostestes[#Data],9)=0,"-",VLOOKUP($B17,casostestes[#Data],9)),"-") -> Resultado 1:' Tarefa de BI criada com situação Pendente. Divergência de autodeclaração (116) incluída na tarefa Após execução workflow: Tarefa de BI com situação alterada para Exigência . Status SIBE igual a FLUXO NÃO INICIADO DTP: Campo Exige_autodeclaração = 1 Resultado 2 - Após alguns minutos: Tarefa de BI com situação alterada para Pendente Despacho incluído informando a operação ( fragmento de sigla XXXXXXXXXX ) Divergência de autodeclaração (116) EXCLUÍDA da tarefa Alguns minutos depois: Status SIBE igual a AGUARDANDO PERÍCIA Na opção "Lista de Ocorrências", o json de integração com o SIBE deverá conter o campo "periodosPendentesSegEsp" com valor null.
B18: =IF(ISERR(casostestes[[#This Row],[ID]]),"-",casostestes[[#This Row],[ID]]) -> 11 | C18: =IFERROR(IF(VLOOKUP($B18,casostestes[#Data],10)=0,"Não",VLOOKUP($B18,casostestes[#Data],10)), "-") -> Sim | D18: =IFERROR(IF(VLOOKUP($B18,casostestes[#Data],2)=0,"-",VLOOKUP($B18,casostestes[#Data],2)), "-") -> Requerimento Inicial de BI | E18: =IFERROR(IF(VLOOKUP($B18,casostestes[#Data],3)=0,"-",VLOOKUP($B18,casostestes[#Data],3)), "-") -> 24 Criar tarefa de BI inicial fluxo ATESTMEDQ para categoria diferente de "Segurado especial" onde o parâmetro "Exige Autodeclaração" no Catálogo está ATIVADO **Parâmetro PAT ligado: 144 - Fluxo ATESTMEDQ | F18: =IFERROR(IF(VLOOKUP($B18,casostestes[#Data],4)=0,"-",VLOOKUP($B18,casostestes[#Data],4)),"-") -> EC | G18: =IFERROR(IF(VLOOKUP($B18,casostestes[#Data],5)=0,"-",VLOOKUP($B18,casostestes[#Data],5)),"-") -> ENTIDADE_CONVENIADA | H18: =IFERROR(IF(VLOOKUP($B18,casostestes[#Data],6)=0,"-",VLOOKUP($B18,casostestes[#Data],6)),"-") -> 1. Logar no Portal do Atendimento INSS com o perfil do caso de teste 2.Criar tarefa de BI informando: Tipo de Incapacidade? "Temporária " A pessoa está presa? Não Categoria do trabalhador diferente de "Segurado Especial" | I18: =IFERROR(IF(VLOOKUP($B18,casostestes[#Data],8)=0,"-",VLOOKUP($B18,casostestes[#Data],8)),"-") -> - | J18: =IFERROR(IF(VLOOKUP($B18,casostestes[#Data],9)=0,"-",VLOOKUP($B18,casostestes[#Data],9)),"-") -> Tarefa de BI criada com situação Pendente. Tarefa SEM Divergência de autodeclaração (116) Status SIBE igual a FLUXO NÃO INICIADO DPT: Tarefa.Exige_autodeclaração = 0
B19: =IF(ISERR(casostestes[[#This Row],[ID]]),"-",casostestes[[#This Row],[ID]]) -> 12 | C19: =IFERROR(IF(VLOOKUP($B19,casostestes[#Data],10)=0,"Não",VLOOKUP($B19,casostestes[#Data],10)), "-") -> Sim | D19: =IFERROR(IF(VLOOKUP($B19,casostestes[#Data],2)=0,"-",VLOOKUP($B19,casostestes[#Data],2)), "-") -> Integração | E19: =IFERROR(IF(VLOOKUP($B19,casostestes[#Data],3)=0,"-",VLOOKUP($B19,casostestes[#Data],3)), "-") -> 26 Criar tarefa de BI inicial fluxo ATESTMEDQ para categoria "Segurado especial" onde o parâmetro "Exige Autodeclaração" no Catálogo está ATIVADO e a autodeclaração tem período pendente **Parâmetro PAT ligado: 144 - Fluxo ATESTMEDQ | F19: =IFERROR(IF(VLOOKUP($B19,casostestes[#Data],4)=0,"-",VLOOKUP($B19,casostestes[#Data],4)),"-") -> EC | G19: =IFERROR(IF(VLOOKUP($B19,casostestes[#Data],5)=0,"-",VLOOKUP($B19,casostestes[#Data],5)),"-") -> ENTIDADE_CONVENIADA | H19: =IFERROR(IF(VLOOKUP($B19,casostestes[#Data],6)=0,"-",VLOOKUP($B19,casostestes[#Data],6)),"-") -> 1. Logar no Portal do Atendimento INSS com o perfil do caso de teste 2.Criar tarefa de BI informando: Tipo de Incapacidade? "Temporária " A pessoa está presa? Não Categoria do trabalhador "Segurado Especial" A pessoa ficou sem trabalhar? Sim 3. Cumprir exigência de documentos obrigatórios 4. Responder formulário da autodeclaração | I19: =IFERROR(IF(VLOOKUP($B19,casostestes[#Data],8)=0,"-",VLOOKUP($B19,casostestes[#Data],8)),"-") -> - | J19: =IFERROR(IF(VLOOKUP($B19,casostestes[#Data],9)=0,"-",VLOOKUP($B19,casostestes[#Data],9)),"-") -> Tarefa de BI criada com situação Pendente. Tarefa SEM Divergência de autodeclaração (116) Status SIBE igual a FLUXO NÃO INICIADO Aguardar até a geração automática do PDF da autodeclaração: DTP: Campo Exige_autodeclaração = 1 Campo DT_RETORNO_SES_CNIS deverá estar preenchido (Descritivo preenchido pelo CNIS) Tabela SES_CNIS_ANALISES (Indica a existência ou não de períodos pendentes) Status SIBE igual a AGUARDANDO ATESTADO Na opção "Lista de Ocorrências", o json de integração com o SIBE deverá conter o campo "periodosPendentesSegEsp" com valor true.
... B200: =IF(ISERR(casostestes[[#This Row],[ID]]),"-",casostestes[[#This Row],[ID]]) -> - | C200: =IFERROR(IF(VLOOKUP($B200,casostestes[#Data],10)=0,"Não",VLOOKUP($B200,casostestes[#Data],10)), "-") -> - | D200: =IFERROR(IF(VLOOKUP($B200,casostestes[#Data],2)=0,"-",VLOOKUP($B200,casostestes[#Data],2)), "-") -> - | E200: =IFERROR(IF(VLOOKUP($B200,casostestes[#Data],3)=0,"-",VLOOKUP($B200,casostestes[#Data],3)), "-") -> - | F200: =IFERROR(IF(VLOOKUP($B200,casostestes[#Data],4)=0,"-",VLOOKUP($B200,casostestes[#Data],4)),"-") -> - | G200: =IFERROR(IF(VLOOKUP($B200,casostestes[#Data],5)=0,"-",VLOOKUP($B200,casostestes[#Data],5)),"-") -> - | H200: =IFERROR(IF(VLOOKUP($B200,casostestes[#Data],6)=0,"-",VLOOKUP($B200,casostestes[#Data],6)),"-") -> - | I200: =IFERROR(IF(VLOOKUP($B200,casostestes[#Data],8)=0,"-",VLOOKUP($B200,casostestes[#Data],8)),"-") -> - | J200: =IFERROR(IF(VLOOKUP($B200,casostestes[#Data],9)=0,"-",VLOOKUP($B200,casostestes[#Data],9)),"-") -> -

Sheet CONFIG
B2: CANAL | D2: PAPEL | F2: STATUS | H2: MACROPROCESSO | J2: HOMOLOGADORES
B3: Central 135 | D3: ATENDENTE_CENTRAL_135 | F3: Aprovado | H3: Requerimento Inicial de BI | J3: Aciria
B4: EC | D4: ENTIDADE_CONVENIADA | F4: Disponível para reteste | H4: Integração | J4: Alexandre
B5: EC - ECT | D5: ENTIDADE_CONVENIADA_CORREIOS | F5: Não Executado
B6: Meu INSS | D6: INTERESSADO | F6: Pendência Externa
B7: PAT | D7: SERVIDOR | F7: Reprovado
F8: Sem massa
F9: Em Teste

Sheet CTS
B1: Portal de Atendimento do INSS - PAT
B2: Autodeclaração do Benefício por Incapacidade
B3: Casos de testes | Cenários
B5: Objetivo:
B7: ID | C7: MACROPROCESSO | D7: CASO DE TESTE | E7: CANAL | F7: PAPEL | G7: FLUXO | H7: MASSA | I7: PARAMETROS | J7: RESULTADO ESPERADO | K7: LIBERADO | L7: ASSUNTO
B8: =IF(B7="ID",1,B7+1) -> 1 | C8: Requerimento Inicial de BI | D8: 6 Criação de tarefa de BI inicial com fluxo ATESTMED para categoria DIFERENTE de Segurado Especial COM exigência de preenchimento da AD. Premissas: Catálogo: Exige autodeclaração = ATIVADO Parâmetro: 144 - Fluxo ATESTMED = LIGADO | E8: Central 135 | F8: ATENDENTE_CENTRAL_135 | G8: 1. Logar no Portal do Atendimento INSS com o perfil do caso de teste 2. Criar tarefa de BI informando: - Tipo de Incapacidade? "Temporário" - A pessoa está presa? "Não" - Categoria do trabalhador "Desempregado" ... - A pessoa ficou sem trabalhar? "Sim" | J8: 1. Na conclusão do requerimento é emitido o aviso: "É necessário apresentar os documentos no prazo de 5 dias. Caso não apresente, o pedido será cancelado." 2. A tarefa de BI criada com STATUS: EM EXIGÊNCIA 3. Status SIBE: Fluxo não iniciado 4. Tarefa COM as divergências: - 174 Ausência do atestado médico | K8: Sim
B9: =IF(B8="ID",1,B8+1) -> 2 | C9: Integração | D9: 12 Criar tarefa de BI inicial fluxo ATESTMEDQ para categoria "Segurado especial" onde o parâmetro "Exige Autodeclaração" no Catálogo está ATIVADO e foi respondida a autodeclaração COM período pendente **Parâmetro PAT ligado: 144 - Fluxo ATESTMEDQ | E9: PAT | F9: SERVIDOR | G9: 1. Logar no Portal do Atendimento INSS com o perfil do caso de teste 2.Criar tarefa de BI informando: Tipo de Incapacidade? "Temporária " A pessoa está presa? Não Categoria do trabalhador "Segurado Especial" A pessoa ficou sem trabalhar? Sim 3. Responder formulário da autodeclaração | J9: Tarefa de BI criada com situação Pendente. Tarefa SEM Divergência de autodeclaração (116) Status SIBE igual a FLUXO NÃO INICIADO Aguardar até a geração automática do PDF da autodeclaração: DTP: Campo Exige_autodeclaração = 1 Campo DT_RETORNO_SES_CNIS deverá estar preenchido (Descritivo preenchido pelo CNIS) Tabela SES_CNIS_ANALISES (Indica a existência ou não de períodos pendentes) Status SIBE igual a AGUARDANDO ATESTADO Na opção "Lista de Ocorrências", o json de integração com o SIBE deverá conter o campo "periodosPendentesSegEsp" com valor true. | K9: Sim
B10: =IF(B9="ID",1,B9+1) -> 3 | C10: Integração | D10: 13 Criar tarefa de BI inicial fluxo ATESTMEDQ para categoria "Segurado especial" onde o parâmetro "Exige Autodeclaração" no Catálogo está ATIVADO e foi respondida a autodeclaração SEM período pendente **Parâmetro PAT ligado: 144 - Fluxo ATESTMEDQ | E10: PAT | F10: SERVIDOR | G10: 1. Logar no Portal do Atendimento INSS com o perfil do caso de teste 2.Criar tarefa de BI informando: Tipo de Incapacidade? "Temporária " A pessoa está presa? Não Categoria do trabalhador "Segurado Especial" A pessoa ficou sem trabalhar? Sim 3. Responder a autodeclaração | J10: Tarefa de BI criada com situação Pendente. Tarefa SEM Divergência de autodeclaração (116) Status SIBE igual a FLUXO NÃO INICIADO Aguardar até a geração automática do PDF da autodeclaração: DTP: Campo Exige_autodeclaração = 1 Campo DT_RETORNO_SES_CNIS deverá estar preenchido (Descritivo preenchido pelo CNIS) Tabela SES_CNIS_ANALISES (Indica a existência ou não de períodos pendentes) Status SIBE igual a AGUARDANDO ATESTADO Na opção "Lista de Ocorrências", o json de integração com o SIBE deverá conter o campo "periodosPendentesSegEsp" com valor false. | K10: Sim
B11: =IF(B10="ID",1,B10+1) -> 4 | C11: Integração | D11: 16 Cumprir a exigência de autodeclaração | E11: PAT | F11: SERVIDOR | G11: 1. Logar no Portal do Atendimento INSS com o perfil Servidor 2.Consultar uma tarefa em exigência de autodeclaração e acionar Cumprir Exigência 3. Responder o formulário de autodeclaração até o final | J11: Tarefa de BI com situação alterada para Pendente Divergência de autodeclaração (116) EXCLUÍDA da tarefa Aguardar até a geração automática do PDF da autodeclaração: DTP: Campo DT_RETORNO_SES_CNIS deverá estar preenchido (Descritivo preenchido pelo CNIS) Tabela SES_CNIS_ANALISES (Indica a existência ou não de períodos pendentes) Status SIBE igual a AGUARDANDO ATESTADO ou AGUARDANDO PERÍCIA (conforme a tarefa seja do fluxo ATESTMEDQ ou PRESENCIAL) Na opção "Lista de Ocorrências", o json de integração com o SIBE deverá conter o campo "periodosPendentesSegEsp" com valor true ou false, conforme tenha ou não períodos pendentes. | K11: Sim
B12: =IF(B11="ID",1,B11+1) -> 5 | C12: Integração | D12: 17 Responder o formulário de autodeclaração acessando diretamente a aba segurado especial ao detalhar a tarefa, onde a tarefa encontra-se em exigência de autodeclaração | E12: PAT | F12: SERVIDOR | G12: 1. Logar no Portal do Atendimento INSS com o perfil Servidor 2.Consultar uma tarefa em exigência de autodeclaração 3. Acionar a aba Segurado especial 3. Responder o formulário de autodeclaração até o final | J12: Tarefa de BI com situação alterada para Pendente Divergência de autodeclaração (116) EXCLUÍDA da tarefa Aguardar até a geração automática do PDF da autodeclaração: Status SIBE igual a AGUARDANDO ATESTADO ou AGUARDANDO PERÍCIA (conforme a tarefa seja do fluxo ATESTMEDQ ou PRESENCIAL) Na opção "Lista de Ocorrências", o json de integração com o SIBE deverá conter o campo "periodosPendentesSegEsp" com valor true ou false, conforme tenha ou não períodos pendentes. | K12: Sim
B13: =IF(B12="ID",1,B12+1) -> 6 | C13: Integração | D13: 18 Responder o formulário de autodeclaração acessando diretamente a aba segurado especial ao detalhar a tarefa, onde a tarefa encontra-se em exigência de documento médico | E13: PAT | F13: SERVIDOR | G13: 1. Logar no Portal do Atendimento INSS com o perfil Servidor 2.Consultar uma tarefa em exigência de documento médico 3. Acionar a aba Segurado especial 3. Responder o formulário de autodeclaração até o final | J13: Tarefa de BI permanece em tarefa em exigência de documento médico Divergência de autodeclaração (116) EXCLUÍDA da tarefa Aguardar até a geração automática do PDF da autodeclaração: Status SIBE continua igual a FLUXO NÃO INICIADO, pois a tarefa encontra-se em exigência de documento médico | K13: Sim
B14: =IF(B13="ID",1,B13+1) -> 7 | C14: Integração | D14: 19 Criar tarefa de BI inicial fluxo ATESTMEDQ para categoria "Segurado especial" onde o parâmetro "Exige Autodeclaração" no Catálogo está ATIVADO, NÃO foi respondida a autodeclaração, NÃO foi incluído o anexo detalhado de AD e cidadão está preso **Parâmetro PAT ligado: 144 - Fluxo ATESTMEDQ | E14: PAT | F14: SERVIDOR | G14: 1. Logar no Portal do Atendimento INSS com o perfil do caso de teste 2.Criar tarefa de BI informando: Tipo de Incapacidade? "Temporária " A pessoa está presa? Sim Categoria do trabalhador "Segurado Especial" A pessoa ficou sem trabalhar? Sim 3. NÃO Informar anexo detalhado de autodeclaração 4. NÃO responder o formulário de autodeclaração | J14: Tarefa de BI criada com situação Pendente. Divergência de autodeclaração (116) incluída na tarefa Após execução workflow: Tarefa de BI com situação alterada para Exigência . Após alguns minutos: Tarefa de BI com situação Concluída. Status SIBE igual a INDEFERIDO Na opção "Lista de Ocorrências", o json de integração com o SIBE deverá conter o campo "periodosPendentesSegEsp" com valor NULL DTP: Campo Exige_autodeclaração = 0 | K14: Sim
B15: =IF(B14="ID",1,B14+1) -> 8 | C15: Integração | D15: 20 Criar tarefa de BI inicial fluxo ATESTMEDQ para categoria "Segurado especial" onde o parâmetro "Exige Autodeclaração" no Catálogo está ATIVADO, NÃO foi respondida a autodeclaração, NÃO foi incluído o anexo detalhado de AD e cidadão ficou sem trabalhar **Parâmetro PAT ligado: 144 - Fluxo ATESTMEDQ | E15: PAT | F15: SERVIDOR | G15: 1. Logar no Portal do Atendimento INSS com o perfil do caso de teste 2.Criar tarefa de BI informando: Tipo de Incapacidade? "Temporária " A pessoa está presa? Não Categoria do trabalhador "Segurado Especial" A pessoa ficou sem trabalhar? Não 3. Informar anexo detalhado de autodeclaração 4. NÃO responder o formulário de autodeclaração | J15: Tarefa de BI criada com situação Pendente. Divergência de autodeclaração (116) incluída na tarefa Após execução workflow: Tarefa de BI com situação alterada para Exigência . Após alguns minutos: Tarefa de BI com situação Concluída. Status SIBE igual a INDEFERIDO Na opção "Lista de Ocorrências", o json de integração com o SIBE deverá conter o campo "periodosPendentesSegEsp" com valor NULL DTP: Campo Exige_autodeclaração = 0 | K15: Sim
B16: =IF(B15="ID",1,B15+1) -> 9 | C16: Integração | D16: 21 Criar tarefa de BI inicial fluxo ATESTMEDQ para categoria "Segurado especial" onde o parâmetro "Exige Autodeclaração" no Catálogo está ATIVADO, NÃO foi respondida a autodeclaração e foi incluído o anexo detalhado de AD **Parâmetro PAT ligado: 144 - Fluxo ATESTMEDQ | E16: PAT | F16: SERVIDOR | G16: 1. Logar no Portal do Atendimento INSS com o perfil do caso de teste 2.Criar tarefa de BI informando: Tipo de Incapacidade? "Temporária " A pessoa está presa? Não Categoria do trabalhador "Segurado Especial" A pessoa ficou sem trabalhar? Sim 3. Informar anexo detalhado de autodeclaração 4. NÃO responder o formulário de autodeclaração Resultado 1 5.Alterar via banco de dados a data da exigência para (data atual - 36 dias) Resultado 2 | J16: Resultado 1:' Tarefa de BI criada com situação Pendente. Divergência de autodeclaração (116) incluída na tarefa Após execução workflow: Tarefa de BI com situação alterada para Exigência . Status SIBE igual a FLUXO NÃO INICIADO DTP: Campo Exige_autodeclaração = 2 Resultado 2 - Após alguns minutos: Tarefa de BI com situação alterada para Pendente Despacho incluído informando a operação ( fragmento de sigla XXXXXXXXXX ) Divergência de autodeclaração (116) EXCLUÍDA da tarefa Alguns minutos depois: Status SIBE igual a AGUARDANDO ATESTADO Na opção "Lista de Ocorrências", o json de integração com o SIBE deverá conter o campo "periodosPendentesSegEsp" com valor true. | K16: Sim
B17: =IF(B16="ID",1,B16+1) -> 10 | C17: Integração | D17: 22 Criar tarefa de BI inicial fluxo PRESENCIAL para categoria "Segurado especial" onde o parâmetro "Exige Autodeclaração" no Catálogo está ATIVADO, NÃO foi respondida a autodeclaração e NÃO foi incluído o anexo detalhado de AD **Parâmetro PAT ligado: 144 - Fluxo ATESTMEDQ **Parâmetro PAT ligado: 109 -Tipo de Incapacidade Permanente leva à Fluxo Presencial do Novo BI | E17: PAT | F17: SERVIDOR | G17: 1. Logar no Portal do Atendimento INSS com o perfil do caso de teste 2.Criar tarefa de BI informando: Tipo de Incapacidade? "Permanente" A pessoa está presa? Não Houve acidente de trabalho? Não Categoria do trabalhador "Segurado Especial" A pessoa ficou sem trabalhar? Sim 3. NÃO informar anexo detalhado de autodeclaração 5. Realizar agendamento 6. NÃO responder o formulário de autodeclaração Resultado 1 7.Alterar via banco de dados a data da exigência para (data atual - 36 dias) Resulado 2 | J17: Resultado 1:' Tarefa de BI criada com situação Pendente. Divergência de autodeclaração (116) incluída na tarefa Após execução workflow: Tarefa de BI com situação alterada para Exigência . Status SIBE igual a FLUXO NÃO INICIADO DTP: Campo Exige_autodeclaração = 1 Resultado 2 - Após alguns minutos: Tarefa de BI com situação alterada para Pendente Despacho incluído informando a operação ( fragmento de sigla XXXXXXXXXX ) Divergência de autodeclaração (116) EXCLUÍDA da tarefa Alguns minutos depois: Status SIBE igual a AGUARDANDO PERÍCIA Na opção "Lista de Ocorrências", o json de integração com o SIBE deverá conter o campo "periodosPendentesSegEsp" com valor null. | K17: Sim
B18: =IF(B17="ID",1,B17+1) -> 11 | C18: Requerimento Inicial de BI | D18: 24 Criar tarefa de BI inicial fluxo ATESTMEDQ para categoria diferente de "Segurado especial" onde o parâmetro "Exige Autodeclaração" no Catálogo está ATIVADO **Parâmetro PAT ligado: 144 - Fluxo ATESTMEDQ | E18: EC | F18: ENTIDADE_CONVENIADA | G18: 1. Logar no Portal do Atendimento INSS com o perfil do caso de teste 2.Criar tarefa de BI informando: Tipo de Incapacidade? "Temporária " A pessoa está presa? Não Categoria do trabalhador diferente de "Segurado Especial" | J18: Tarefa de BI criada com situação Pendente. Tarefa SEM Divergência de autodeclaração (116) Status SIBE igual a FLUXO NÃO INICIADO DPT: Tarefa.Exige_autodeclaração = 0 | K18: Sim
B19: =IF(B18="ID",1,B18+1) -> 12 | C19: Integração | D19: 26 Criar tarefa de BI inicial fluxo ATESTMEDQ para categoria "Segurado especial" onde o parâmetro "Exige Autodeclaração" no Catálogo está ATIVADO e a autodeclaração tem período pendente **Parâmetro PAT ligado: 144 - Fluxo ATESTMEDQ | E19: EC | F19: ENTIDADE_CONVENIADA | G19: 1. Logar no Portal do Atendimento INSS com o perfil do caso de teste 2.Criar tarefa de BI informando: Tipo de Incapacidade? "Temporária " A pessoa está presa? Não Categoria do trabalhador "Segurado Especial" A pessoa ficou sem trabalhar? Sim 3. Cumprir exigência de documentos obrigatórios 4. Responder formulário da autodeclaração | J19: Tarefa de BI criada com situação Pendente. Tarefa SEM Divergência de autodeclaração (116) Status SIBE igual a FLUXO NÃO INICIADO Aguardar até a geração automática do PDF da autodeclaração: DTP: Campo Exige_autodeclaração = 1 Campo DT_RETORNO_SES_CNIS deverá estar preenchido (Descritivo preenchido pelo CNIS) Tabela SES_CNIS_ANALISES (Indica a existência ou não de períodos pendentes) Status SIBE igual a AGUARDANDO ATESTADO Na opção "Lista de Ocorrências", o json de integração com o SIBE deverá conter o campo "periodosPendentesSegEsp" com valor true. | K19: Sim
... B34: =IF(B33="ID",1,B33+1) -> 27 | C34: Integração | D34: 43' Criar tarefa de BI inicial fluxo ATESTMEDQ para categoria "Segurado especial" onde o parâmetro "Exige Autodeclaração" no Catálogo está ATIVADO, NÃO foi respondida a autodeclaração, NÃO foi incluído o anexo detalhado de AD e ocorreu enquadramento na regra da análise de risco **Parâmetro PAT ligado: 144 - Fluxo ATESTMEDQ **Parâmetro PAT ligado: 119 - Habilitar fluxo de Análise de Risco no Novo BI | E34: PAT | F34: SERVIDOR | G34: 1. Logar no Portal do Atendimento INSS com o perfil do caso de teste 2.Criar tarefa de BI informando: Tipo de Incapacidade? "Temporária " A pessoa está presa? Não Categoria do trabalhador "Segurado Especial" A pessoa ficou sem trabalhar? Sim 3. NÃO informar anexo detalhado de autodeclaração 4. NÃO responder o formulário de autodeclaração Resultado 1 5. Executar o serviço do STD simulando enquadramento na regra da análise de risco - Inclusão da divergência 202 (ORIENTAÇÕES NA ABA MASSA) Resultado 2 6. Cumprir a exigência, respondendo o formulário de autodeclaração Resultado 3 | J34: 'Resultado 1: Tarefa de BI criada com situação Pendente e COM Divergência de autodeclaração (116) Após alguns minutos, tarefa de BI alterada para Exigência . Status SIBE igual a FLUXO NÃO INICIADO "Fluxo Inicial do BI" deve ter o valor "ATESTMEDQ" "Fluxo Final do BI" deve ter o valor "ATESTMEDQ" DTP: Campo Exige_autodeclaração = 1 Resultado 2 - Após a execução do serviço do STD: -Cerca de 5 minutos depois, será exibida a divergência da Análise de Risco (202) no requerimento Status SIBE continua igual a FLUXO NÃO INICIADO Resultado 3 - após cumpris exigência de AD: Tarefa de BI com situação Pendente Divergência de falta de autodeclaração (116) excluída da tarefa Aguardar até a geração automática do PDF da autodeclaração: -Alguns minutos depois: Status SIBE igual a AGUARDANDO PERÍCIA -Ocorrências de integração (com SIBE) "tipoInformacaoMedica":0 "periodosPendentesSegEsp" com valor true ou false, conforme tenha ou não períodos pendentes. Seção campos adicionais: "Fluxo Inicial do BI" deve ter o valor "ATESTMEDQ" "Fluxo Final do BI" deve ter o valor "PRESENCIAL" -Alguns minutos depois, o requerimento entrará em exigência de agendamento: Seção "Agendamentos (Perícia)": - A etapa_pericia apresentará o valor AGUARDANDO AGENDAMENTO Aba Despachos: -Inclusão do despacho de exigência de agendamento | K34: Sim

Sheet ACOMPANHAMENTO
B1: Portal de Atendimento do INSS - PAT
B2: Autodeclaração para o Requerimento de Benefício por Incapacidade
B3: Homologador:
B7: # | C7: LIBERADO | D7: MACROPROCESSO | E7: CASO DE TESTE | F7: CANAL | G7: PAPEL | H7: FLUXO | I7: PARÂMETROS | J7: RESULTADO ESPERADO | K7: Orlando | L7: Mauricio | M7: Thaisa | N7: Carlos | O7: Alessandra | P7: Ana_Carolina | Q7: Wanei | R7: Janaina | S7: Andreia | T7: homologador
B8: =IF(ISERR(casostestes[[#This Row],[ID]]),"-",casostestes[[#This Row],[ID]]) -> 1 | C8: =IFERROR(IF(VLOOKUP($B8,casostestes[#Data],10)=0,"Não",VLOOKUP($B8,casostestes[#Data],10)), "-") -> Sim | D8: =IFERROR(IF(VLOOKUP($B8,casostestes[#Data],2)=0,"-",VLOOKUP($B8,casostestes[#Data],2)), "-") -> Requerimento Inicial de BI | E8: =IFERROR(IF(VLOOKUP($B8,casostestes[#Data],3)=0,"-",VLOOKUP($B8,casostestes[#Data],3)), "-") -> 6 Criação de tarefa de BI inicial com fluxo ATESTMED para categoria DIFERENTE de Segurado Especial COM exigência de preenchimento da AD. Premissas: Catálogo: Exige autodeclaração = ATIVADO Parâmetro: 144 - Fluxo ATESTMED = LIGADO | F8: =IFERROR(IF(VLOOKUP($B8,casostestes[#Data],4)=0,"-",VLOOKUP($B8,casostestes[#Data],4)),"-") -> Central 135 | G8: =IFERROR(IF(VLOOKUP($B8,casostestes[#Data],5)=0,"-",VLOOKUP($B8,casostestes[#Data],5)),"-") -> ATENDENTE_CENTRAL_135 | H8: =IFERROR(IF(VLOOKUP($B8,casostestes[#Data],6)=0,"-",VLOOKUP($B8,casostestes[#Data],6)),"-") -> 1. Logar no Portal do Atendimento INSS com o perfil do caso de teste 2. Criar tarefa de BI informando: - Tipo de Incapacidade? "Temporário" - A pessoa está presa? "Não" - Categoria do trabalhador "Desempregado" ... - A pessoa ficou sem trabalhar? "Sim" | I8: =IFERROR(IF(VLOOKUP($B8,casostestes[#Data],8)=0,"-",VLOOKUP($B8,casostestes[#Data],8)),"-") -> - | J8: =IFERROR(IF(VLOOKUP($B8,casostestes[#Data],9)=0,"-",VLOOKUP($B8,casostestes[#Data],9)),"-") -> 1. Na conclusão do requerimento é emitido o aviso: "É necessário apresentar os documentos no prazo de 5 dias. Caso não apresente, o pedido será cancelado." 2. A tarefa de BI criada com STATUS: EM EXIGÊNCIA 3. Status SIBE: Fluxo não iniciado 4. Tarefa COM as divergências: - 174 Ausência do atestado médico | K8: =IFERROR(IF(VLOOKUP($B8,orlando[#Data],12)=0,"Não executado",VLOOKUP($B8,orlando[#Data],12)),"Não executado") -> Não executado | L8: =IFERROR(IF(VLOOKUP($B8,mauricio[#Data],12)=0,"Não executado",VLOOKUP($B8,mauricio[#Data],12)),"Não executado") -> Não executado | M8: =IFERROR(IF(VLOOKUP($B8,Thaisa[#Data],12)=0,"Não executado",VLOOKUP($B8,Thaisa[#Data],12)),"Não executado") -> Não executado | N8: =IFERROR(IF(VLOOKUP($B8,carlos[#Data],12)=0,"Não executado",VLOOKUP($B8,carlos[#Data],12)),"Não executado") -> Aprovado | O8: =IFERROR(IF(VLOOKUP($B8,Alessandra[#Data],12)=0,"Não executado",VLOOKUP($B8,Alessandra[#Data],12)),"Não executado") -> Não executado | P8: =IFERROR(IF(VLOOKUP($B8,AnaCarolina[#Data],12)=0,"Não executado",VLOOKUP($B8,AnaCarolina[#Data],12)),"Não executado") -> Aprovado | Q8: =IFERROR(IF(VLOOKUP($B8,wanei[#Data],12)=0,"Não executado",VLOOKUP($B8,wanei[#Data],12)),"Não executado") -> Aprovado | R8: =IFERROR(IF(VLOOKUP($B8,janaina[#Data],12)=0,"Não executado",VLOOKUP($B8,janaina[#Data],12)),"Não executado") -> Aprovado | S8: =IFERROR(IF(VLOOKUP($B8,andreia[#Data],12)=0,"Não executado",VLOOKUP($B8,andreia[#Data],12)),"Não executado") -> Aprovado | T8: =IFERROR(IF(VLOOKUP(#REF!,homologador[#Data],12)=0,"Não executado",VLOOKUP(#REF!,homologador[#Data],12)),"Não executado") -> Não executado | U8: =COUNTIF(ACOMPANHAMENTO!K8:T8,"Aprovado")+COUNTIF(K8:T8,"Reprovado")+COUNTIF(K8:T8,"Em Teste") -> 5 | V8: =COUNTIF(K8:T8,"Em Teste") -> 0 | W8: =IF(U8>3,IF(V8>1,"SIM","NÃO"),"NÃO") -> NÃO
B9: =IF(ISERR(casostestes[[#This Row],[ID]]),"-",casostestes[[#This Row],[ID]]) -> 2 | C9: =IFERROR(IF(VLOOKUP($B9,casostestes[#Data],10)=0,"Não",VLOOKUP($B9,casostestes[#Data],10)), "-") -> Sim | D9: =IFERROR(IF(VLOOKUP($B9,casostestes[#Data],2)=0,"-",VLOOKUP($B9,casostestes[#Data],2)), "-") -> Integração | E9: =IFERROR(IF(VLOOKUP($B9,casostestes[#Data],3)=0,"-",VLOOKUP($B9,casostestes[#Data],3)), "-") -> 12 Criar tarefa de BI inicial fluxo ATESTMEDQ para categoria "Segurado especial" onde o parâmetro "Exige Autodeclaração" no Catálogo está ATIVADO e foi respondida a autodeclaração COM período pendente **Parâmetro PAT ligado: 144 - Fluxo ATESTMEDQ | F9: =IFERROR(IF(VLOOKUP($B9,casostestes[#Data],4)=0,"-",VLOOKUP($B9,casostestes[#Data],4)),"-") -> PAT | G9: =IFERROR(IF(VLOOKUP($B9,casostestes[#Data],5)=0,"-",VLOOKUP($B9,casostestes[#Data],5)),"-") -> SERVIDOR | H9: =IFERROR(IF(VLOOKUP($B9,casostestes[#Data],6)=0,"-",VLOOKUP($B9,casostestes[#Data],6)),"-") -> 1. Logar no Portal do Atendimento INSS com o perfil do caso de teste 2.Criar tarefa de BI informando: Tipo de Incapacidade? "Temporária " A pessoa está presa? Não Categoria do trabalhador "Segurado Especial" A pessoa ficou sem trabalhar? Sim 3. Responder formulário da autodeclaração | I9: =IFERROR(IF(VLOOKUP($B9,casostestes[#Data],8)=0,"-",VLOOKUP($B9,casostestes[#Data],8)),"-") -> - | J9: =IFERROR(IF(VLOOKUP($B9,casostestes[#Data],9)=0,"-",VLOOKUP($B9,casostestes[#Data],9)),"-") -> Tarefa de BI criada com situação Pendente. Tarefa SEM Divergência de autodeclaração (116) Status SIBE igual a FLUXO NÃO INICIADO Aguardar até a geração automática do PDF da autodeclaração: DTP: Campo Exige_autodeclaração = 1 Campo DT_RETORNO_SES_CNIS deverá estar preenchido (Descritivo preenchido pelo CNIS) Tabela SES_CNIS_ANALISES (Indica a existência ou não de períodos pendentes) Status SIBE igual a AGUARDANDO ATESTADO Na opção "Lista de Ocorrências", o json de integração com o SIBE deverá conter o campo "periodosPendentesSegEsp" com valor true. | K9: =IFERROR(IF(VLOOKUP($B9,orlando[#Data],12)=0,"Não executado",VLOOKUP($B9,orlando[#Data],12)),"Não executado") -> Não executado | L9: =IFERROR(IF(VLOOKUP($B9,mauricio[#Data],12)=0,"Não executado",VLOOKUP($B9,mauricio[#Data],12)),"Não executado") -> Aprovado | M9: =IFERROR(IF(VLOOKUP($B9,Thaisa[#Data],12)=0,"Não executado",VLOOKUP($B9,Thaisa[#Data],12)),"Não executado") -> Não executado | N9: =IFERROR(IF(VLOOKUP($B9,carlos[#Data],12)=0,"Não executado",VLOOKUP($B9,carlos[#Data],12)),"Não executado") -> Aprovado | O9: =IFERROR(IF(VLOOKUP($B9,Alessandra[#Data],12)=0,"Não executado",VLOOKUP($B9,Alessandra[#Data],12)),"Não executado") -> Não executado | P9: =IFERROR(IF(VLOOKUP($B9,AnaCarolina[#Data],12)=0,"Não executado",VLOOKUP($B9,AnaCarolina[#Data],12)),"Não executado") -> Aprovado | Q9: =IFERROR(IF(VLOOKUP($B9,wanei[#Data],12)=0,"Não executado",VLOOKUP($B9,wanei[#Data],12)),"Não executado") -> Aprovado | R9: =IFERROR(IF(VLOOKUP($B9,janaina[#Data],12)=0,"Não executado",VLOOKUP($B9,janaina[#Data],12)),"Não executado") -> Disponível para reteste | S9: =IFERROR(IF(VLOOKUP($B9,andreia[#Data],12)=0,"Não executado",VLOOKUP($B9,andreia[#Data],12)),"Não executado") -> Aprovado | T9: =IFERROR(IF(VLOOKUP(#REF!,homologador[#Data],12)=0,"Não executado",VLOOKUP(#REF!,homologador[#Data],12)),"Não executado") -> Não executado | U9: =COUNTIF(ACOMPANHAMENTO!K9:T9,"Aprovado")+COUNTIF(K9:T9,"Reprovado")+COUNTIF(K9:T9,"Em Teste") -> 5 | V9: =COUNTIF(K9:T9,"Em Teste") -> 0 | W9: =IF(U9>3,IF(V9>1,"SIM","NÃO"),"NÃO") -> NÃO
B10: =IF(ISERR(casostestes[[#This Row],[ID]]),"-",casostestes[[#This Row],[ID]]) -> 3 | C10: =IFERROR(IF(VLOOKUP($B10,casostestes[#Data],10)=0,"Não",VLOOKUP($B10,casostestes[#Data],10)), "-") -> Sim | D10: =IFERROR(IF(VLOOKUP($B10,casostestes[#Data],2)=0,"-",VLOOKUP($B10,casostestes[#Data],2)), "-") -> Integração | E10: =IFERROR(IF(VLOOKUP($B10,casostestes[#Data],3)=0,"-",VLOOKUP($B10,casostestes[#Data],3)), "-") -> 13 Criar tarefa de BI inicial fluxo ATESTMEDQ para categoria "Segurado especial" onde o parâmetro "Exige Autodeclaração" no Catálogo está ATIVADO e foi respondida a autodeclaração SEM período pendente **Parâmetro PAT ligado: 144 - Fluxo ATESTMEDQ | F10: =IFERROR(IF(VLOOKUP($B10,casostestes[#Data],4)=0,"-",VLOOKUP($B10,casostestes[#Data],4)),"-") -> PAT | G10: =IFERROR(IF(VLOOKUP($B10,casostestes[#Data],5)=0,"-",VLOOKUP($B10,casostestes[#Data],5)),"-") -> SERVIDOR | H10: =IFERROR(IF(VLOOKUP($B10,casostestes[#Data],6)=0,"-",VLOOKUP($B10,casostestes[#Data],6)),"-") -> 1. Logar no Portal do Atendimento INSS com o perfil do caso de teste 2.Criar tarefa de BI informando: Tipo de Incapacidade? "Temporária " A pessoa está presa? Não Categoria do trabalhador "Segurado Especial" A pessoa ficou sem trabalhar? Sim 3. Responder a autodeclaração | I10: =IFERROR(IF(VLOOKUP($B10,casostestes[#Data],8)=0,"-",VLOOKUP($B10,casostestes[#Data],8)),"-") -> - | J10: =IFERROR(IF(VLOOKUP($B10,casostestes[#Data],9)=0,"-",VLOOKUP($B10,casostestes[#Data],9)),"-") -> Tarefa de BI criada com situação Pendente. Tarefa SEM Divergência de autodeclaração (116) Status SIBE igual a FLUXO NÃO INICIADO Aguardar até a geração automática do PDF da autodeclaração: DTP: Campo Exige_autodeclaração = 1 Campo DT_RETORNO_SES_CNIS deverá estar preenchido (Descritivo preenchido pelo CNIS) Tabela SES_CNIS_ANALISES (Indica a existência ou não de períodos pendentes) Status SIBE igual a AGUARDANDO ATESTADO Na opção "Lista de Ocorrências", o json de integração com o SIBE deverá conter o campo "periodosPendentesSegEsp" com valor false. | K10: =IFERROR(IF(VLOOKUP($B10,orlando[#Data],12)=0,"Não executado",VLOOKUP($B10,orlando[#Data],12)),"Não executado") -> Não executado | L10: =IFERROR(IF(VLOOKUP($B10,mauricio[#Data],12)=0,"Não executado",VLOOKUP($B10,mauricio[#Data],12)),"Não executado") -> Aprovado | M10: =IFERROR(IF(VLOOKUP($B10,Thaisa[#Data],12)=0,"Não executado",VLOOKUP($B10,Thaisa[#Data],12)),"Não executado") -> Não executado | N10: =IFERROR(IF(VLOOKUP($B10,carlos[#Data],12)=0,"Não executado",VLOOKUP($B10,carlos[#Data],12)),"Não executado") -> Disponível para reteste | O10: =IFERROR(IF(VLOOKUP($B10,Alessandra[#Data],12)=0,"Não executado",VLOOKUP($B10,Alessandra[#Data],12)),"Não executado") -> Não executado | P10: =IFERROR(IF(VLOOKUP($B10,AnaCarolina[#Data],12)=0,"Não executado",VLOOKUP($B10,AnaCarolina[#Data],12)),"Não executado") -> Aprovado | Q10: =IFERROR(IF(VLOOKUP($B10,wanei[#Data],12)=0,"Não executado",VLOOKUP($B10,wanei[#Data],12)),"Não executado") -> Aprovado | R10: =IFERROR(IF(VLOOKUP($B10,janaina[#Data],12)=0,"Não executado",VLOOKUP($B10,janaina[#Data],12)),"Não executado") -> Disponível para reteste | S10: =IFERROR(IF(VLOOKUP($B10,andreia[#Data],12)=0,"Não executado",VLOOKUP($B10,andreia[#Data],12)),"Não executado") -> Aprovado | T10: =IFERROR(IF(VLOOKUP(#REF!,homologador[#Data],12)=0,"Não executado",VLOOKUP(#REF!,homologador[#Data],12)),"Não executado") -> Não executado | U10: =COUNTIF(ACOMPANHAMENTO!K10:T10,"Aprovado")+COUNTIF(K10:T10,"Reprovado")+COUNTIF(K10:T10,"Em Teste") -> 4 | V10: =COUNTIF(K10:T10,"Em Teste") -> 0 | W10: =IF(U10>3,IF(V10>1,"SIM","NÃO"),"NÃO") -> NÃO
B11: =IF(ISERR(casostestes[[#This Row],[ID]]),"-",casostestes[[#This Row],[ID]]) -> 4 | C11: =IFERROR(IF(VLOOKUP($B11,casostestes[#Data],10)=0,"Não",VLOOKUP($B11,casostestes[#Data],10)), "-") -> Sim | D11: =IFERROR(IF(VLOOKUP($B11,casostestes[#Data],2)=0,"-",VLOOKUP($B11,casostestes[#Data],2)), "-") -> Integração | E11: =IFERROR(IF(VLOOKUP($B11,casostestes[#Data],3)=0,"-",VLOOKUP($B11,casostestes[#Data],3)), "-") -> 16 Cumprir a exigência de autodeclaração | F11: =IFERROR(IF(VLOOKUP($B11,casostestes[#Data],4)=0,"-",VLOOKUP($B11,casostestes[#Data],4)),"-") -> PAT | G11: =IFERROR(IF(VLOOKUP($B11,casostestes[#Data],5)=0,"-",VLOOKUP($B11,casostestes[#Data],5)),"-") -> SERVIDOR | H11: =IFERROR(IF(VLOOKUP($B11,casostestes[#Data],6)=0,"-",VLOOKUP($B11,casostestes[#Data],6)),"-") -> 1. Logar no Portal do Atendimento INSS com o perfil Servidor 2.Consultar uma tarefa em exigência de autodeclaração e acionar Cumprir Exigência 3. Responder o formulário de autodeclaração até o final | I11: =IFERROR(IF(VLOOKUP($B11,casostestes[#Data],8)=0,"-",VLOOKUP($B11,casostestes[#Data],8)),"-") -> - | J11: =IFERROR(IF(VLOOKUP($B11,casostestes[#Data],9)=0,"-",VLOOKUP($B11,casostestes[#Data],9)),"-") -> Tarefa de BI com situação alterada para Pendente Divergência de autodeclaração (116) EXCLUÍDA da tarefa Aguardar até a geração automática do PDF da autodeclaração: DTP: Campo DT_RETORNO_SES_CNIS deverá estar preenchido (Descritivo preenchido pelo CNIS) Tabela SES_CNIS_ANALISES (Indica a existência ou não de períodos pendentes) Status SIBE igual a AGUARDANDO ATESTADO ou AGUARDANDO PERÍCIA (conforme a tarefa seja do fluxo ATESTMEDQ ou PRESENCIAL) Na opção "Lista de Ocorrências", o json de integração com o SIBE deverá conter o campo "periodosPendentesSegEsp" com valor true ou false, conforme tenha ou não períodos pendentes. | K11: =IFERROR(IF(VLOOKUP($B11,orlando[#Data],12)=0,"Não executado",VLOOKUP($B11,orlando[#Data],12)),"Não executado") -> Não executado | L11: =IFERROR(IF(VLOOKUP($B11,mauricio[#Data],12)=0,"Não executado",VLOOKUP($B11,mauricio[#Data],12)),"Não executado") -> Aprovado | M11: =IFERROR(IF(VLOOKUP($B11,Thaisa[#Data],12)=0,"Não executado",VLOOKUP($B11,Thaisa[#Data],12)),"Não executado") -> Não executado | N11: =IFERROR(IF(VLOOKUP($B11,carlos[#Data],12)=0,"Não executado",VLOOKUP($B11,carlos[#Data],12)),"Não executado") -> Disponível para reteste | O11: =IFERROR(IF(VLOOKUP($B11,Alessandra[#Data],12)=0,"Não executado",VLOOKUP($B11,Alessandra[#Data],12)),"Não executado") -> Não executado | P11: =IFERROR(IF(VLOOKUP($B11,AnaCarolina[#Data],12)=0,"Não executado",VLOOKUP($B11,AnaCarolina[#Data],12)),"Não executado") -> Aprovado | Q11: =IFERROR(IF(VLOOKUP($B11,wanei[#Data],12)=0,"Não executado",VLOOKUP($B11,wanei[#Data],12)),"Não executado") -> Aprovado | R11: =IFERROR(IF(VLOOKUP($B11,janaina[#Data],12)=0,"Não executado",VLOOKUP($B11,janaina[#Data],12)),"Não executado") -> Aprovado | S11: =IFERROR(IF(VLOOKUP($B11,andreia[#Data],12)=0,"Não executado",VLOOKUP($B11,andreia[#Data],12)),"Não executado") -> Aprovado | T11: =IFERROR(IF(VLOOKUP(#REF!,homologador[#Data],12)=0,"Não executado",VLOOKUP(#REF!,homologador[#Data],12)),"Não executado") -> Não executado | U11: =COUNTIF(ACOMPANHAMENTO!K11:T11,"Aprovado")+COUNTIF(K11:T11,"Reprovado")+COUNTIF(K11:T11,"Em Teste") -> 5 | V11: =COUNTIF(K11:T11,"Em Teste") -> 0 | W11: =IF(U11>3,IF(V11>1,"SIM","NÃO"),"NÃO") -> NÃO
B12: =IF(ISERR(casostestes[[#This Row],[ID]]),"-",casostestes[[#This Row],[ID]]) -> 5 | C12: =IFERROR(IF(VLOOKUP($B12,casostestes[#Data],10)=0,"Não",VLOOKUP($B12,casostestes[#Data],10)), "-") -> Sim | D12: =IFERROR(IF(VLOOKUP($B12,casostestes[#Data],2)=0,"-",VLOOKUP($B12,casostestes[#Data],2)), "-") -> Integração | E12: =IFERROR(IF(VLOOKUP($B12,casostestes[#Data],3)=0,"-",VLOOKUP($B12,casostestes[#Data],3)), "-") -> 17 Responder o formulário de autodeclaração acessando diretamente a aba segurado especial ao detalhar a tarefa, onde a tarefa encontra-se em exigência de autodeclaração | F12: =IFERROR(IF(VLOOKUP($B12,casostestes[#Data],4)=0,"-",VLOOKUP($B12,casostestes[#Data],4)),"-") -> PAT | G12: =IFERROR(IF(VLOOKUP($B12,casostestes[#Data],5)=0,"-",VLOOKUP($B12,casostestes[#Data],5)),"-") -> SERVIDOR | H12: =IFERROR(IF(VLOOKUP($B12,casostestes[#Data],6)=0,"-",VLOOKUP($B12,casostestes[#Data],6)),"-") -> 1. Logar no Portal do Atendimento INSS com o perfil Servidor 2.Consultar uma tarefa em exigência de autodeclaração 3. Acionar a aba Segurado especial 3. Responder o formulário de autodeclaração até o final | I12: =IFERROR(IF(VLOOKUP($B12,casostestes[#Data],8)=0,"-",VLOOKUP($B12,casostestes[#Data],8)),"-") -> - | J12: =IFERROR(IF(VLOOKUP($B12,casostestes[#Data],9)=0,"-",VLOOKUP($B12,casostestes[#Data],9)),"-") -> Tarefa de BI com situação alterada para Pendente Divergência de autodeclaração (116) EXCLUÍDA da tarefa Aguardar até a geração automática do PDF da autodeclaração: Status SIBE igual a AGUARDANDO ATESTADO ou AGUARDANDO PERÍCIA (conforme a tarefa seja do fluxo ATESTMEDQ ou PRESENCIAL) Na opção "Lista de Ocorrências", o json de integração com o SIBE deverá conter o campo "periodosPendentesSegEsp" com valor true ou false, conforme tenha ou não períodos pendentes. | K12: =IFERROR(IF(VLOOKUP($B12,orlando[#Data],12)=0,"Não executado",VLOOKUP($B12,orlando[#Data],12)),"Não executado") -> Não executado | L12: =IFERROR(IF(VLOOKUP($B12,mauricio[#Data],12)=0,"Não executado",VLOOKUP($B12,mauricio[#Data],12)),"Não executado") -> Aprovado | M12: =IFERROR(IF(VLOOKUP($B12,Thaisa[#Data],12)=0,"Não executado",VLOOKUP($B12,Thaisa[#Data],12)),"Não executado") -> Não executado | N12: =IFERROR(IF(VLOOKUP($B12,carlos[#Data],12)=0,"Não executado",VLOOKUP($B12,carlos[#Data],12)),"Não executado") -> Aprovado | O12: =IFERROR(IF(VLOOKUP($B12,Alessandra[#Data],12)=0,"Não executado",VLOOKUP($B12,Alessandra[#Data],12)),"Não executado") -> Não executado | P12: =IFERROR(IF(VLOOKUP($B12,AnaCarolina[#Data],12)=0,"Não executado",VLOOKUP($B12,AnaCarolina[#Data],12)),"Não executado") -> Em Teste | Q12: =IFERROR(IF(VLOOKUP($B12,wanei[#Data],12)=0,"Não executado",VLOOKUP($B12,wanei[#Data],12)),"Não executado") -> Aprovado | R12: =IFERROR(IF(VLOOKUP($B12,janaina[#Data],12)=0,"Não executado",VLOOKUP($B12,janaina[#Data],12)),"Não executado") -> Aprovado | S12: =IFERROR(IF(VLOOKUP($B12,andreia[#Data],12)=0,"Não executado",VLOOKUP($B12,andreia[#Data],12)),"Não executado") -> Aprovado | T12: =IFERROR(IF(VLOOKUP(#REF!,homologador[#Data],12)=0,"Não executado",VLOOKUP(#REF!,homologador[#Data],12)),"Não executado") -> Não executado | U12: =COUNTIF(ACOMPANHAMENTO!K12:T12,"Aprovado")+COUNTIF(K12:T12,"Reprovado")+COUNTIF(K12:T12,"Em Teste") -> 6 | V12: =COUNTIF(K12:T12,"Em Teste") -> 1 | W12: =IF(U12>3,IF(V12>1,"SIM","NÃO"),"NÃO") -> NÃO
